Workbook

Sheet Raw_Data
A1: session_id | B1: datetime | C1: hour | D1: day_of_week | E1: is_weekend | F1: temperature | G1: wholesale_price | H1: retail_price | I1: charging_sessions | J1: energy_per_session | K1: energy_sold_kwh | L1: predicted_energy_sold_kwh | M1: normalized_demand | N1: demand_multiplier | O1: time_multiplier | P1: dynamic_price | Q1: dynamic_revenue | R1: dynamic_cost | S1: dynamic_profit | T1: Adjusted_demand | U1: static_markup_percent | V1: static_retail_price | W1: static_revenue | X1: static_cost | Y1: static_profit
A2: 1 | B2: 2025-01-01 00:00:00 | C2: 0 | D2: 2 | E2: 0 | F2: 25.127134 | G2: 0.18831877 | H2: 0.23539846 | I2: 5 | J2: 13.923257 | K2: 69.616286 | L2: 106.85045 | M2: 0.3341254 | N2: 1.1670627 | O2: 1 | P2: 0.27472477 | Q2: 23.90136 | R2: 16.383942 | S2: 7.5174175 | T2: 87.001109 | U2: 0.25 | V2: 0.18759988 | W2: 20.045131 | X2: 20.121945 | Y2: -0.076814028
A3: 2 | B3: 2025-01-01 01:00:00 | C3: 1 | D3: 2 | E3: 0 | F3: 25.190453 | G3: 0.18224089 | H3: 0.22780111 | I3: 3 | J3: 25.697249 | K3: 77.091747 | L3: 63.715196 | M3: 0.19923983 | N3: 1.0996199 | O3: 1 | P3: 0.25049464 | Q3: 13.819972 | R3: 10.054363 | S3: 3.7656092 | T3: 55.170729 | U3: 0.25 | V3: 0.18759988 | W3: 11.952963 | X3: 11.611514 | Y3: 0.34144899
A4: 3 | B4: 2025-01-01 02:00:00 | C4: 2 | D4: 2 | E4: 0 | F4: 27.573437 | G4: 0.20682758 | H4: 0.25853448 | I4: 1 | J4: 25.714565 | K4: 25.714565 | L4: 24.707828 | M4: 0.077262316 | N4: 1.0386312 | O4: 1 | P4: 0.2714612 | Q4: 5.5079067 | R4: 4.1965003 | S4: 1.3114063 | T4: 20.289849 | U4: 0.25 | V4: 0.18759988 | W4: 4.6351856 | X4: 5.1102604 | Y4: -0.47507474
A5: 4 | B5: 2025-01-01 03:00:00 | C5: 3 | D5: 2 | E5: 0 | F5: 28.977748 | G5: 0.19858248 | H5: 0.2482281 | I5: 2 | J5: 20.320314 | K5: 40.640627 | L5: 50.080246 | M5: 0.15660283 | N5: 1.0783014 | O5: 1 | P5: 0.26766472 | Q5: 11.116342 | R5: 8.2472983 | S5: 2.8690435 | T5: 41.530845 | U5: 0.25 | V5: 0.18759988 | W5: 9.3950481 | X5: 9.9450597 | Y5: -0.55001155
A6: 5 | B6: 2025-01-01 04:00:00 | C6: 4 | D6: 2 | E6: 0 | F6: 28.294179 | G6: 0.20809431 | H6: 0.26011789 | I6: 2 | J6: 24.234807 | K6: 48.469613 | L6: 48.107129 | M6: 0.15043282 | N6: 1.0752164 | O6: 1 | P6: 0.27968303 | Q6: 10.813049 | R6: 8.045301 | S6: 2.7677485 | T6: 38.661801 | U6: 0.25 | V6: 0.18759988 | W6: 9.0248915 | X6: 10.01082 | Y6: -0.9859284
A7: 6 | B7: 2025-01-01 05:00:00 | C7: 5 | D7: 2 | E7: 0 | F7: 28.893787 | G7: 0.21032931 | H7: 0.26291163 | I7: 1 | J7: 21.268573 | K7: 21.268573 | L7: 27.644226 | M7: 0.086444544 | N7: 1.0432223 | O7: 1 | P7: 0.27605722 | Q7: 6.1920434 | R7: 4.7177473 | S7: 1.474296 | T7: 22.43029 | U7: 0.25 | V7: 0.18759988 | W7: 5.1860535 | X7: 5.814391 | Y7: -0.62833746
A8: 7 | B8: 2025-01-01 06:00:00 | C8: 6 | D8: 2 | E8: 0 | F8: 30.866844 | G8: 0.18646606 | H8: 0.23308258 | I8: 6 | J8: 30.525788 | K8: 183.15473 | L8: 142.05142 | M8: 0.44420017 | N8: 1.2221001 | O8: 1 | P8: 0.28485024 | Q8: 32.073016 | R8: 20.995345 | S8: 11.077671 | T8: 112.59606 | U8: 0.25 | V8: 0.18759988 | W8: 26.648829 | X8: 26.487769 | Y8: 0.16106016
A9: 8 | B9: 2025-01-01 07:00:00 | C9: 7 | D9: 2 | E9: 0 | F9: 30.22336 | G9: 0.19286237 | H9: 0.24107796 | I9: 6 | J9: 18.998655 | K9: 113.99193 | L9: 140.29927 | M9: 0.43872115 | N9: 1.2193606 | O9: 1.2 | P9: 0.35275315 | Q9: 32.063276 | R9: 17.530104 | S9: 14.533172 | T9: 90.894372 | U9: 0.25 | V9: 0.18759988 | W9: 26.320127 | X9: 27.05845 | Y9: -0.73832301
A10: 9 | B10: 2025-01-01 08:00:00 | C10: 8 | D10: 2 | E10: 0 | F10: 30.914536 | G10: 0.16707479 | H10: 0.20884348 | I10: 8 | J10: 27.129697 | K10: 217.03758 | L10: 186.50401 | M10: 0.58320513 | N10: 1.2916026 | O10: 1.2 | P10: 0.32369133 | Q10: 42.852014 | R10: 22.118266 | S10: 20.733748 | T10: 132.38542 | U10: 0.25 | V10: 0.18759988 | W10: 34.98813 | X10: 31.160118 | Y10: 3.8280122
A11: 10 | B11: 2025-01-01 09:00:00 | C11: 9 | D11: 2 | E11: 0 | F11: 28.663114 | G11: 0.1498351 | H11: 0.18729387 | I11: 8 | J11: 25.83659 | K11: 206.69272 | L11: 181.98821 | M11: 0.56908404 | N11: 1.284542 | O11: 1.2 | P11: 0.28870422 | Q11: 41.21432 | R11: 21.389891 | S11: 19.824429 | T11: 142.75621 | U11: 0.25 | V11: 0.18759988 | W11: 34.140967 | X11: 27.268222 | Y11: 6.8727449
A12: 11 | B12: 2025-01-01 10:00:00 | C12: 10 | D12: 2 | E12: 0 | F12: 27.655256 | G12: 0.13049162 | H12: 0.16311453 | I12: 5 | J12: 19.292819 | K12: 96.464093 | L12: 115.14182 | M12: 0.36005283 | N12: 1.1800264 | O12: 1 | P12: 0.19247945 | Q12: 21.931851 | R12: 14.868719 | S12: 7.0631324 | T12: 113.94386 | U12: 0.25 | V12: 0.18759988 | W12: 21.600591 | X12: 15.025043 | Y12: 6.5755484
A13: 12 | B13: 2025-01-01 11:00:00 | C13: 11 | D13: 2 | E13: 0 | F13: 26.936426 | G13: 0.11673582 | H13: 0.14591978 | I13: 6 | J13: 25.87122 | K13: 155.22732 | L13: 135.81017 | M13: 0.42468355 | N13: 1.2123418 | O13: 1 | P13: 0.17690464 | Q13: 24.573334 | R13: 16.21545 | S13: 8.3578842 | T13: 138.90723 | U13: 0.25 | V13: 0.18759988 | W13: 25.477971 | X13: 15.853912 | Y13: 9.6240593
... A2881: 2880 | B2881: 2025-04-30 23:00:00 | C2881: 23 | D2881: 2 | E2881: 0 | F2881: 23.719133 | G2881: 0.19204871 | H2881: 0.24006089 | I2881: 1 | J2881: 21.830667 | K2881: 21.830667 | L2881: 16.462687 | M2881: 0.051479447 | N2881: 1.0257397 | O2881: 1 | P2881: 0.25206393 | Q2881: 3.5792799 | R2881: 2.7270704 | S2881: 0.85220951 | T2881: 14.199889 | U2881: 0.25 | V2881: 0.18759988 | W2881: 3.0883981 | X2881: 3.1616379 | Y2881: -0.073239738

Sheet Data
A1: session_id | B1: datetime | C1: hour | D1: wholesale_price | E1: predicted_energy_sold_kwh | F1: Adjusted_demand | G1: dynamic_price | H1: dynamic_cost | I1: dynamic_revenue | J1: static_retail_price | K1: static_revenue | L1: demand_multiplier | M1: time_multiplier
A2: 1 | B2: 2025-01-01 00:00:00 | C2: 0 | D2: 0.18831877 | E2: 106.85045 | F2: 87.001109 | G2: 0.27472477 | H2: 16.383942 | I2: 23.90136 | J2: 0.18759988 | K2: 20.045131 | L2: 1.1670627 | M2: 1
A3: 2 | B3: 2025-01-01 01:00:00 | C3: 1 | D3: 0.18224089 | E3: 63.715196 | F3: 55.170729 | G3: 0.25049464 | H3: 10.054363 | I3: 13.819972 | J3: 0.18759988 | K3: 11.952963 | L3: 1.0996199 | M3: 1
A4: 3 | B4: 2025-01-01 02:00:00 | C4: 2 | D4: 0.20682758 | E4: 24.707828 | F4: 20.289849 | G4: 0.2714612 | H4: 4.1965003 | I4: 5.5079067 | J4: 0.18759988 | K4: 4.6351856 | L4: 1.0386312 | M4: 1
A5: 4 | B5: 2025-01-01 03:00:00 | C5: 3 | D5: 0.19858248 | E5: 50.080246 | F5: 41.530845 | G5: 0.26766472 | H5: 8.2472983 | I5: 11.116342 | J5: 0.18759988 | K5: 9.3950481 | L5: 1.0783014 | M5: 1
A6: 5 | B6: 2025-01-01 04:00:00 | C6: 4 | D6: 0.20809431 | E6: 48.107129 | F6: 38.661801 | G6: 0.27968303 | H6: 8.045301 | I6: 10.813049 | J6: 0.18759988 | K6: 9.0248915 | L6: 1.0752164 | M6: 1
A7: 6 | B7: 2025-01-01 05:00:00 | C7: 5 | D7: 0.21032931 | E7: 27.644226 | F7: 22.43029 | G7: 0.27605722 | H7: 4.7177473 | I7: 6.1920434 | J7: 0.18759988 | K7: 5.1860535 | L7: 1.0432223 | M7: 1
A8: 7 | B8: 2025-01-01 06:00:00 | C8: 6 | D8: 0.18646606 | E8: 142.05142 | F8: 112.59606 | G8: 0.28485024 | H8: 20.995345 | I8: 32.073016 | J8: 0.18759988 | K8: 26.648829 | L8: 1.2221001 | M8: 1
A9: 8 | B9: 2025-01-01 07:00:00 | C9: 7 | D9: 0.19286237 | E9: 140.29927 | F9: 90.894372 | G9: 0.35275315 | H9: 17.530104 | I9: 32.063276 | J9: 0.18759988 | K9: 26.320127 | L9: 1.2193606 | M9: 1.2
A10: 9 | B10: 2025-01-01 08:00:00 | C10: 8 | D10: 0.16707479 | E10: 186.50401 | F10: 132.38542 | G10: 0.32369133 | H10: 22.118266 | I10: 42.852014 | J10: 0.18759988 | K10: 34.98813 | L10: 1.2916026 | M10: 1.2
A11: 10 | B11: 2025-01-01 09:00:00 | C11: 9 | D11: 0.1498351 | E11: 181.98821 | F11: 142.75621 | G11: 0.28870422 | H11: 21.389891 | I11: 41.21432 | J11: 0.18759988 | K11: 34.140967 | L11: 1.284542 | M11: 1.2
A12: 11 | B12: 2025-01-01 10:00:00 | C12: 10 | D12: 0.13049162 | E12: 115.14182 | F12: 113.94386 | G12: 0.19247945 | H12: 14.868719 | I12: 21.931851 | J12: 0.18759988 | K12: 21.600591 | L12: 1.1800264 | M12: 1
A13: 12 | B13: 2025-01-01 11:00:00 | C13: 11 | D13: 0.11673582 | E13: 135.81017 | F13: 138.90723 | G13: 0.17690464 | H13: 16.21545 | I13: 24.573334 | J13: 0.18759988 | K13: 25.477971 | L13: 1.2123418 | M13: 1
... A2881: 2880 | B2881: 2025-04-30 23:00:00 | C2881: 23 | D2881: 0.19204871 | E2881: 16.462687 | F2881: 14.199889 | G2881: 0.25206393 | H2881: 2.7270704 | I2881: 3.5792799 | J2881: 0.18759988 | K2881: 3.0883981 | L2881: 1.0257397 | M2881: 1

Sheet Summary
A2: We are assuming that there is a -0.4 demand elasticity with the dynamic price
A3: Financial Summary
A4: Metrics | B4: Static Pricing | C4: Dynamic Pricing
A5: Total Energy Sold (kWh) | B5: =SUM(Data!E2:E2881) -> 359411.96 | C5: =SUM(Data!F2:F2881) -> 313146.06
A6: Average Price | B6: =AVERAGE(Data!J2:J2881) -> 0.18759988 | C6: =AVERAGE(Data!G2:G2881) -> 0.24176075
A7: Total Revenue | B7: =SUMPRODUCT(Data!J2:J2881,Data!E2:E2881) -> 67425.64 | C7: =SUMPRODUCT(Data!G2:G2881,Data!F2:F2881) -> 74829.14
A8: Total Cost | B8: =SUMPRODUCT(Data!D2:D2881,Data!E2:E2881) -> 50800.017 | C8: =SUMPRODUCT(Data!D2:D2881,Data!F2:F2881) -> 43153.217
A9: Total Profit | B9: =B7-B8 -> 16625.623 | C9: =C7-C8 -> 31675.923
A11: KPIs
A12: Profit Increase % | B12: =(C9-B9)/B9 -> 0.9052473
A13: Average Price Increase % | B13: =(C6-B6)/B6 -> 0.28870419

Sheet Sensitivity_analysis
A1: Assumptions
A2: Base Margin | B2: 0.2
A3: Demand Adjustment | B3: 1
A4: Wholesales price multiplier | B4: 1
A6: Dynamic Pricing | D6: Static Pricing
A7: Adjusted Demand | B7: =Summary!C5 -> 313146.06 | D7: Predicted Energy sold | E7: =Summary!B5 -> 359411.96
A8: Total Revenue | B8: =Summary!C7 -> 74829.14 | D8: Total Revenue | E8: =Summary!B7 -> 67425.64
A9: Total cost | B9: =Summary!C8 -> 43153.217 | D9: Total cost | E9: =Summary!B8 -> 50800.017
A10: Total Profit | B10: =Summary!C9 -> 31675.923 | D10: Total Profit | E10: =Summary!B9 -> 16625.623
A11: Profit Margin | B11: =B10/B9 -> 0.73403386 | D11: Profit Margin | E11: =E10/E9 -> 0.32727593
A12: Testing for profit under different demand scenarios (What if demand increases or decreases)
A13: With Dynamic pricing
A14: Demand Adjustment | B14: Multiplier | C14: Total Revenue | D14: Total Cost | E14: Total Profit | F14: Profit Margin %
A15: 0.8 (20% below) | B15: 0.8 | C15: {=SUMPRODUCT(Data!G2:G2881 * B15,Data!F2:F2881)} -> 59863.312 | D15: {=SUMPRODUCT(Data!F2:F2881 * B15, Data!D2:D2881)} -> 34522.574 | E15: =C15-D15 -> 25340.738 | F15: =(C15-D15)/D15 -> 0.73403386
A16: 0.9 (10% below) | B16: 0.9 | C16: {=SUMPRODUCT(Data!G2:G2881 * B16,Data!F2:F2881)} -> 67346.226 | D16: {=SUMPRODUCT(Data!F2:F2881 * B16, Data!D2:D2881)} -> 38837.896 | E16: =C16-D16 -> 28508.331 | F16: =(C16-D16)/D16 -> 0.73403386
A17: 1 (baseline) | B17: 1 | C17: {=SUMPRODUCT(Data!G2:G2881 * B17,Data!F2:F2881)} -> 74829.14 | D17: {=SUMPRODUCT(Data!F2:F2881 * B17, Data!D2:D2881)} -> 43153.217 | E17: =C17-D17 -> 31675.923 | F17: =E17/D17 -> 0.73403386
A18: 1.1 (10% above) | B18: 1.1 | C18: {=SUMPRODUCT(Data!G2:G2881 * B18,Data!F2:F2881)} -> 82312.054 | D18: {=SUMPRODUCT(Data!F2:F2881 * B18, Data!D2:D2881)} -> 47468.539 | E18: =C18-D18 -> 34843.515 | F18: =E18/D18 -> 0.73403386
A19: 1.2 (20% above) | B19: 1.2 | C19: {=SUMPRODUCT(Data!G2:G2881 * B19,Data!F2:F2881)} -> 89794.968 | D19: {=SUMPRODUCT(Data!F2:F2881 * B19, Data!D2:D2881)} -> 51783.861 | E19: =C19-D19 -> 38011.107 | F19: =E19/D19 -> 0.73403386
A21: With static_pricing
A22: Demand Adjustment | B22: Multiplier | C22: Total Revenue | D22: Total Cost | E22: Total Profit | F22: Profit Margin %
A23: 0.8 (20% below) | B23: 0.8 | C23: {=SUMPRODUCT(Data!E10:E2889 * B23,Data!J10:J2889)} -> 53849.946 | D23: {=SUMPRODUCT(Data!E10:E2889 * B23, Data!D10:D2889)} -> 40547.086 | E23: =C23-D23 -> 13302.86 | F23: =(C23-D23)/D23 -> 0.32808424
A24: 0.9 (10% below) | B24: 0.9 | C24: {=SUMPRODUCT(Data!E10:E2889 * B24,Data!J10:J2889)} -> 60581.189 | D24: {=SUMPRODUCT(Data!E10:E2889 * B24, Data!D10:D2889)} -> 45615.471 | E24: =C24-D24 -> 14965.717 | F24: =(C24-D24)/D24 -> 0.32808424
A25: 1 (baseline) | B25: 1 | C25: {=SUMPRODUCT(Data!E10:E2889 * B25,Data!J10:J2889)} -> 67312.432 | D25: {=SUMPRODUCT(Data!E10:E2889 * B25, Data!D10:D2889)} -> 50683.857 | E25: =C25-D25 -> 16628.575 | F25: =E25/D25 -> 0.32808424
A26: 1.1 (10% above) | B26: 1.1 | C26: {=SUMPRODUCT(Data!E10:E2889 * B26,Data!J10:J2889)} -> 74043.675 | D26: {=SUMPRODUCT(Data!E10:E2889 * B26, Data!D10:D2889)} -> 55752.243 | E26: =C26-D26 -> 18291.432 | F26: =E26/D26 -> 0.32808424
A27: 1.2 (20% above) | B27: 1.2 | C27: {=SUMPRODUCT(Data!E10:E2889 * B27,Data!J10:J2889)} -> 80774.918 | D27: {=SUMPRODUCT(Data!E10:E2889 * B27, Data!D10:D2889)} -> 60820.629 | E27: =C27-D27 -> 19954.29 | F27: =E27/D27 -> 0.32808424
A30: Testing for profit under different wholesale scenarios (What if the wholesale price increases)
A31: With dynamic Pricing
A32: dynamic_price" = retail_price * demand_multiplier * time_multiplier, any change in the wholesale price will affect the retail price (wholesale price * 1.25), a 25% markup is used, then the dynamic price.
A33: Price Adjustment | B33: Multiplier | C33: Total Dynamic Price | D33: Total Revenue | E33: Total Cost | F33: Total Profit | G33: Profit Margin %
A34: 0.8 (reduces by 20%) | B34: 0.8 | C34: {=SUMPRODUCT(Data!D2:D2881 * B34 * 1.25, Data!L2:L2881,Data!M2:M2881)} -> 556.26272 | D34: {=SUMPRODUCT(Data!D2:D2881 * B34 * 1.25, Data!L2:L2881,Data!M2:M2881, Data!F2:F2881)} -> 59855.82 | E34: {=SUMPRODUCT(Data!D2:D2881 * B34, Data!F2:F2881)} -> 34522.574 | F34: =D34-E34 -> 25333.246 | G34: =F34/E34 -> 0.73381684
A35: 0.9 (reduces by 10%) | B35: 0.9 | C35: {=SUMPRODUCT(Data!D2:D2881 * B35 * 1.25, Data!L2:L2881,Data!M2:M2881)} -> 625.79556 | D35: {=SUMPRODUCT(Data!D2:D2881 * B35 * 1.25, Data!L2:L2881,Data!M2:M2881, Data!F2:F2881)} -> 67337.798 | E35: {=SUMPRODUCT(Data!D2:D2881 * B35, Data!F2:F2881)} -> 38837.896 | F35: =D35-E35 -> 28499.902 | G35: =F35/E35 -> 0.73381684
A36: 1 (price remains) | B36: 1 | C36: {=SUMPRODUCT(Data!D2:D2881 * B36 * 1.25, Data!L2:L2881,Data!M2:M2881)} -> 695.3284 | D36: {=SUMPRODUCT(Data!D2:D2881 * B36 * 1.25, Data!L2:L2881,Data!M2:M2881, Data!F2:F2881)} -> 74819.775 | E36: {=SUMPRODUCT(Data!D2:D2881 * B36, Data!F2:F2881)} -> 43153.217 | F36: =D36-E36 -> 31666.558 | G36: =F36/E36 -> 0.73381684
A37: 1.1 (increases by 10%) | B37: 1.1 | C37: {=SUMPRODUCT(Data!D2:D2881 * B37 * 1.25, Data!L2:L2881,Data!M2:M2881)} -> 764.86124 | D37: {=SUMPRODUCT(Data!D2:D2881 * B37 * 1.25, Data!L2:L2881,Data!M2:M2881, Data!F2:F2881)} -> 82301.753 | E37: {=SUMPRODUCT(Data!D2:D2881 * B37, Data!F2:F2881)} -> 47468.539 | F37: =D37-E37 -> 34833.213 | G37: =F37/E37 -> 0.73381684
A38: 1.2 (increases by 20%) | B38: 1.2 | C38: {=SUMPRODUCT(Data!D2:D2881 * B38 * 1.25, Data!L2:L2881,Data!M2:M2881)} -> 834.39408 | D38: {=SUMPRODUCT(Data!D2:D2881 * B38 * 1.25, Data!L2:L2881,Data!M2:M2881, Data!F2:F2881)} -> 89783.73 | E38: {=SUMPRODUCT(Data!D2:D2881 * B38, Data!F2:F2881)} -> 51783.861 | F38: =D38-E38 -> 37999.869 | G38: =F38/E38 -> 0.73381684
A41: With Static pricing
A42: Static Retail price = Average (wholesale price) * 1.25
A43: Price Adjustment | B43: Multiplier | C43: Total Static Retail price | D43: Total Revenue | E43: Total Cost | F43: Total Profit | G43: Profit Margin %
A44: 0.8 (reduces by 20%) | B44: 0.8 | C44: {=(AVERAGE(Data!D2:D2881*B44)*1.25)*2881} -> 432.3802 | D44: {=(AVERAGE(Data!D2:D2881*B44)*1.25)*$E$7} -> 53940.512 | E44: {=AVERAGE(Data!D2:D2881*B44)*$E$7} -> 43152.41 | F44: =D44-E44 -> 10788.102 | G44: =F44/E44 -> 0.25
A45: 0.9 (reduces by 10%) | B45: 0.9 | C45: {=(AVERAGE(Data!D2:D2881*B45)*1.25)*2881} -> 486.42773 | D45: {=(AVERAGE(Data!D2:D2881*B45)*1.25)*$E$7} -> 60683.076 | E45: {=AVERAGE(Data!D2:D2881*B45)*$E$7} -> 48546.461 | F45: =D45-E45 -> 12136.615 | G45: =F45/E45 -> 0.25
A46: 1 (price remains) | B46: 1 | C46: {=(AVERAGE(Data!D2:D2881*B46)*1.25)*2881} -> 540.47525 | D46: {=(AVERAGE(Data!D2:D2881*B46)*1.25)*$E$7} -> 67425.64 | E46: {=AVERAGE(Data!D2:D2881*B46)*$E$7} -> 53940.512 | F46: =D46-E46 -> 13485.128 | G46: =F46/E46 -> 0.25
...
